Workbook

Sheet Guide
A1: Sewing Thread Consumption – Master Sheet
A2: One workbook replacing the three ANECALC calculators (Light, Medium, Heavy weight fabrics) with a single dynamic model.
B4: How to use (3 steps)
B5: 1. Setup | C5: Choose the fabric weight class (Light / Medium / Heavy / Custom), confirm seam thickness, waste %, program size, and list your thread SKUs with put-up length and price per cone.
B6: 2. Operations | C6: For each operation pick a stitch type, enter rows, SPI and seam length in cm (or quantity for bartacks / buttonholes / button sew / embroidery), then pick the thread SKU for each thread position. Each row shows a status: ✔ OK or ⚠ with what to fix.
B7: 3. Read the results | C7: Thread Order = metres, cones and cost per thread SKU. Dashboard = KPIs, split by thread position / stitch category, and a what-if table showing the same garment on Light, Medium, Heavy and Custom fabric.
B9: What makes it dynamic
B10: Fabric weight switch | C10: Change one cell on Setup and every factor, thread split and total recalculates. Seam thickness for each class is editable; 'Custom' lets you type any thickness.
B11: SPI interpolation | C11: Decimal SPI (e.g. 11.5) is interpolated between neighbouring SPI columns. Out-of-range SPI is flagged with the valid range for that stitch.
B12: Auto-checks | C12: Missing stitch / length / SPI, thread positions with no SKU, more than 3 rows of needle thread, unassigned metres and thread SKUs missing from the library are all flagged; Thread Order reconciles back to Operations.
B13: What-if sensitivity | C13: Hidden helper columns on Operations (AB:AK, expand with [+]) recompute every row at all four fabric weights so the Dashboard can compare them side by side.
B14: Editable libraries | C14: Stitch Library holds the needle / bobbin / looper / cover splits per fabric weight; Engine holds the factor tables (thread length ÷ seam length) – both can be adjusted.
B16: Colour code
B17: Blue text, yellow fill | C17: Input – safe to edit.
B18: Blue text, white fill | C18: Hard-coded source value from the ANECALC files (library data) – edit only if you have better data.
B19: Black text | C19: Formula – do not overwrite.
B20: Green text | C20: Direct link to another sheet.
B22: How the maths works (same engine as ANECALC)
B23: Thread factor | C23: Factor = thread length ÷ seam length for the chosen stitch type, SPI and seam thickness (t). Examples: 301 lockstitch = 2 + 2·t·SPI; 401 chainstitch = 4 + 2·t·SPI; 504 overedge = 4·SPI·(width + t) + 5 (t in inches).
B24: Operation metres | C24: Total m = seam length (cm) ÷ 100 × factor × rows. For piece-based items the factor is cm of thread per piece, so enter the quantity instead of a length.
B25: Split by position | C25: Needle m = total × needle share (÷ rows when 1–3 rows allowed, so each row can use its own thread), bobbin / looper / cover = total × their shares.
B26: Waste, cones, cost | C26: Incl. waste = net × (1 + waste %). Cones = program size × metres ÷ put-up. Cost per garment = metres incl. waste × price per cone ÷ put-up.
B28: Reconciliation with the three source files (please review)
B29: 401 chainstitch formula | C29: Heavy file uses 4 + 2·t·SPI. Light and Medium files use 4 × 2 · t·SPI (= 8·t·SPI, no constant), which gives roughly 30–40% less thread and looks like a '+' typed as '×'. This master defaults to the corrected formula for all weights. Setup ▸ '401 chainstitch formula' = Original reproduces the Light/Medium file numbers. It also drives 515/401, 516/401, 'Both' safety stitches and 524.
B30: 404 zigzag chain | C30: In the Heavy and Light files the SPI 9 and 10 cells point at the wrong row (a 103 blindstitch value instead of SPI). Rebuilt consistently with the Medium file formula.
B31: 515/503 safety stitch | C31: Light file adds a 304 zigzag term for SPI 6+ but not SPI 5. Heavy and Medium use 503 3/16" only; this master follows them for all weights.
B32: Differences kept as in the source | C32: 516/504 uses the 1/4" overedge in the Heavy and Light files but 3/16" in the Medium file; 411 picoetta is hard-coded in Heavy / Light but formula-driven in Medium; lockstitch SPI 2–4 and all piece-based values differ per weight, as in the originals.
B33: 524 stitches | C33: Only in the Medium file (= 401 + 514). Added for all weights using each weight's own 401 and 514 rows; Medium thread split used for all weights.
B34: Piece-based items | C34: Bartack, button sew, buttonhole, embroidery and cap eyelet carry a fixed thread amount per piece. Interpreted as cm of thread per piece (the original formula divides a 'length' by 100, so entering quantity gives metres) – please confirm against your A&E help guide.
B35: Not carried over | C35: The Help Guide and ISO stitch-matrix pictures in the originals are images only and are not included. The original Light/Heavy price table has 11 thread slots; this one has 15, and the operations table has 80 rows (originals: 40 / 160).
B37: Sample data
B38: Placeholders | C38: The sample garment, thread names, put-up and prices are illustrative only. Clear the yellow cells on Setup (thread library) and Operations to start your own style.

Sheet Setup
A1: Setup – project, fabric weight & thread library
A2: Yellow cells with blue text are inputs. Everything else is calculated.
B4: 1. Project details
B5: Company | C5: Sample Apparel Ltd.
B6: Garment description | C6: SAMPLE – Men's chino trouser (replace)
B7: Style / reference # | C7: STY-0001
B8: Prepared by | C8: Merchandising / Planning
B10: 2. Fabric weight & seam thickness
B11: Fabric weight class (select) | C11: Medium
B13: Class | C13: Avg. seam thickness (mm) | D13: Source / basis
B14: Light | C14: 1.2 | D14: ANECALC Light-Wt file (seam thickness cell Y3 = 1.2 mm)
B15: Medium | C15: 1.9 | D15: ANECALC Medium-Wt file (Y3 = 1.9 mm)
B16: Heavy | C16: 2.9 | D16: ANECALC Heavy-Wt file (Y3 = 2.9 mm)
B17: Custom | C17: 2.4 | D17: Your own thickness – uses Medium-Wt stitch geometry & thread splits
B19: Active class # | C19: =MATCH(C11,B14:B17,0) -> 2
B20: Active seam thickness (mm) | C20: =INDEX(C14:C17,C19) -> 1.9
B21: Active seam thickness (inch) | C21: =C20/25.4 -> 0.07480315
B23: 3. Global parameters
B24: Thread waste allowance (%) | C24: 0.1 | D24: ANECALC default = 10%
B25: Program size (garments) | C25: 10000 | D25: ANECALC default = 10,000 units
B26: Currency label | C26: US $
B27: 401 chainstitch formula (Light / Medium / Custom) | C27: Corrected | D27: Corrected = 4 + 2·t·SPI (as in Heavy file). Original = 8·t·SPI (as typed in Light & Medium files). See Guide.
B29: 4. Thread library (feeds every thread drop-down on the Operations sheet)
B30: Thread description (size / tex, brand, colour) | C30: Put-up (m per cone) | D30: Price per cone | E30: Price per metre
B31: Tex 40 Spun Poly – Khaki (needle) | C31: 5000 | D31: 3.8 | E31: =IF(AND(N(C31)>0,N(D31)>0),D31/C31,"") -> 0.00076
B32: Tex 60 Spun Poly – Khaki (bobbin / looper) | C32: 5000 | D32: 3.2 | E32: =IF(AND(N(C32)>0,N(D32)>0),D32/C32,"") -> 0.00064
B33: Tex 27 Core Poly – Khaki (bartack / buttonhole) | C33: 3000 | D33: 2.6 | E33: =IF(AND(N(C33)>0,N(D33)>0),D33/C33,"") -> 0.00086666667
E34: =IF(AND(N(C34)>0,N(D34)>0),D34/C34,"")
E35: =IF(AND(N(C35)>0,N(D35)>0),D35/C35,"")
E36: =IF(AND(N(C36)>0,N(D36)>0),D36/C36,"")
E37: =IF(AND(N(C37)>0,N(D37)>0),D37/C37,"")
E38: =IF(AND(N(C38)>0,N(D38)>0),D38/C38,"")
E39: =IF(AND(N(C39)>0,N(D39)>0),D39/C39,"")
E40: =IF(AND(N(C40)>0,N(D40)>0),D40/C40,"")
E41: =IF(AND(N(C41)>0,N(D41)>0),D41/C41,"")
E42: =IF(AND(N(C42)>0,N(D42)>0),D42/C42,"")
E43: =IF(AND(N(C43)>0,N(D43)>0),D43/C43,"")
E44: =IF(AND(N(C44)>0,N(D44)>0),D44/C44,"")
E45: =IF(AND(N(C45)>0,N(D45)>0),D45/C45,"")
B46: Sample thread names and prices above are illustrative placeholders – overwrite with your supplier data.

Sheet Operations
A1: Operations – thread consumption by operation
A2: Fill the yellow cells (blue text). Pick a stitch type, enter SPI, rows and seam length (cm) – or quantity for bartacks / buttonholes / embroidery. Pick thread SKUs for each thread position.
B4: Fabric weight | D4: Operations costed | F4: Thread / garment (m) | I4: Incl. waste (m) | L4: Thread cost / garment | P4: Check
B5: =Setup!C11&" ("&TEXT(Setup!C20,"0.0")&" mm)" -> Medium (1.9 mm) | D5: =COUNTIF(I10:I89,">0") -> 9 | F5: =I90 -> 63.253291 | I5: =I90*(1+Waste_Pct) -> 69.57862 | L5: ='Thread Order'!J21 -> 0.047917374 | P5: =IF(COUNTIF(AA10:AA89,"⚠*")=0,"All rows OK",COUNTIF(AA10:AA89,"⚠*")&" row(s) need attention") -> All rows OK
B6: Legend: yellow / blue = input | black = formula | grey SPI = not needed (piece-based item) | ⚠ = fix before using the result
B7: Rows 1–3 of stitching: the needle thread is split equally across Needle 1–3 positions. Sample operations shown are illustrative – overwrite or clear the yellow cells.
A8: OPERATION INPUTS | F8: LENGTH & CONSUMPTION | J8: THREAD SPLIT (from library) | N8: THREAD ASSIGNMENT & METRES | Z8: CHECKS | AB8: HELPERS (grouped – expand with [+])
A9: Op # | B9: Operation name | C9: Stitch type (drop-down) | D9: Rows of stitch | E9: SPI | F9: Seam length (cm) or Qty (pcs) | G9: Unit | H9: Thread factor used | I9: Total thread m / garment | J9: Needle % | K9: Bobbin % | L9: Looper % | M9: Cover % | N9: Needle 1 thread | O9: Needle 1 m | P9: Needle 2 thread | Q9: Needle 2 m | R9: Needle 3 thread | S9: Needle 3 m | T9: Bobbin thread | U9: Bobbin m | V9: Looper thread | W9: Looper m | X9: Cover thread | Y9: Cover m | Z9: Unassigned m | AA9: Status | AB9: Library # | AC9: SPI used | AD9: SPI floor | AE9: SPI fraction | AF9: Multi-row? | AG9: Category | AH9: m @ Light | AI9: m @ Medium | AJ9: m @ Heavy | AK9: m @ Custom
A10: 1 | B10: Front pocket topstitch | C10: 301 Lockstitch | D10: 1 | E10: 12 | F10: 44 | G10: =IF($AB10="","",IF(INDEX(Lib_Basis,$AB10)="Piece","pcs","cm")) -> cm | H10: =IF(OR($AB10="",$AC10="",N($AC10)<1,N($AC10)>24),0,IF($AE10=0,INDEX(Engine_Grid,(WeightIdx-1)*75+$AB10,$AD10),IF(OR($AD10>=24,INDEX(Engine_Grid,(WeightIdx-1)*75+$AB10,$AD10)=0,INDEX(Engine_Grid,(WeightIdx-1)*75+$AB10,$AD10+1)=0),0,INDEX(Engine_Grid,(WeightIdx-1)*75+$AB10,$AD10)*(1-$AE10)+INDEX(Engine_Grid,(WeightIdx-1)*75+$AB10,$AD10+1)*$AE10))) -> 3.7952756 | I10: =IF(OR($H10=0,N($F10)<=0),0,$F10/100*$H10*IF(N($D10)<1,1,$D10)) -> 1.6699213 | J10: =IF($AB10="","",INDEX(Lib_Needle,$AB10)) -> 0.51 | K10: =IF($AB10="","",INDEX(Lib_Bobbin,$AB10)) -> 0.49 | L10: =IF($AB10="","",INDEX(Lib_Looper,$AB10)) -> 0 | M10: =IF($AB10="","",INDEX(Lib_Cover,$AB10)) -> 0 | N10: Tex 40 Spun Poly – Khaki (needle) | O10: =IF($I10=0,0,IF($AF10="Y",$I10*$J10/IF(N($D10)<1,1,$D10),$I10*$J10)) -> 0.85165984 | Q10: =IF(AND($I10>0,$AF10="Y",IF(N($D10)<1,1,$D10)>=2),$I10*$J10/IF(N($D10)<1,1,$D10),0) -> 0 | S10: =IF(AND($I10>0,$AF10="Y",IF(N($D10)<1,1,$D10)>=3),$I10*$J10/IF(N($D10)<1,1,$D10),0) -> 0 | T10: Tex 60 Spun Poly – Khaki (bobbin / looper) | U10: =IF($I10=0,0,$I10*$K10) -> 0.81826142 | W10: =IF($I10=0,0,$I10*$L10) -> 0 | Y10: =IF($I10=0,0,$I10*$M10) -> 0 | Z10: =IF($N10="",$O10,0)+IF($P10="",$Q10,0)+IF($R10="",$S10,0)+IF($T10="",$U10,0)+IF($V10="",$W10,0)+IF($X10="",$Y10,0)+IF(AND($AF10="Y",IF(N($D10)<1,1,$D10)>3),$I10*$J10*(IF(N($D10)<1,1,$D10)-3)/IF(N($D10)<1,1,$D10),0) -> 0 | AA10: =IF(AND($C10="",N($F10)=0),"",IF($C10="","⚠ Select a stitch type",IF($AB10="","⚠ Stitch not in library",IF(N($F10)<=0,"⚠ Enter "&IF($G10="pcs","quantity","seam length (cm)"),IF(AND($G10="cm",N($E10)<=0),"⚠ Enter SPI",IF($H10=0,"⚠ No factor at SPI "&$E10&" – valid "&INDEX(Lib_MinSPI,$AB10)&"–"&INDEX(Lib_MaxSPI,$AB10),IF(AND($AF10="Y",IF(N($D10)<1,1,$D10)>3),"⚠ More than 3 rows – thread for extra rows not allocated",IF($Z10>0.00001,"⚠ Assign threads ("&TEXT($Z10,"0.00")&" m unassigned)","✔ OK")))))))) -> ✔ OK | AB10: =IF($C10="","",IFERROR(MATCH($C10,Lib_Names,0),"")) -> 7 | AC10: =IF($AB10="","",IF(INDEX(Lib_Basis,$AB10)="Piece",1,N($E10))) -> 12 | AD10: =IF($AC10="","",INT($AC10)) -> 12 | AE10: =IF($AC10="","",$AC10-$AD10) -> 0 | AF10: =IF($AB10="","",INDEX(Lib_Multi,$AB10)) -> Y | AG10: =IF($AB10="","",INDEX(Lib_Cat,$AB10)) -> Lockstitch / zigzag | AH10: =IF(N($F10)<=0,0,$F10/100*IF(OR($AB10="",$AC10="",N($AC10)<1,N($AC10)>24),0,IF($AE10=0,INDEX(Engine_Grid,0+$AB10,$AD10),IF(OR($AD10>=24,INDEX(Engine_Grid,0+$AB10,$AD10)=0,INDEX(Engine_Grid,0+$AB10,$AD10+1)=0),0,INDEX(Engine_Grid,0+$AB10,$AD10)*(1-$AE10)+INDEX(Engine_Grid,0+$AB10,$AD10+1)*$AE10)))*IF(N($D10)<1,1,$D10)) -> 1.3788976 | AI10: =IF(N($F10)<=0,0,$F10/100*IF(OR($AB10="",$AC10="",N($AC10)<1,N($AC10)>24),0,IF($AE10=0,INDEX(Engine_Grid,75+$AB10,$AD10),IF(OR($AD10>=24,INDEX(Engine_Grid,75+$AB10,$AD10)=0,INDEX(Engine_Grid,75+$AB10,$AD10+1)=0),0,INDEX(Engine_Grid,75+$AB10,$AD10)*(1-$AE10)+INDEX(Engine_Grid,75+$AB10,$AD10+1)*$AE10)))*IF(N($D10)<1,1,$D10)) -> 1.6699213 | AJ10: =IF(N($F10)<=0,0,$F10/100*IF(OR($AB10="",$AC10="",N($AC10)<1,N($AC10)>24),0,IF($AE10=0,INDEX(Engine_Grid,150+$AB10,$AD10),IF(OR($AD10>=24,INDEX(Engine_Grid,150+$AB10,$AD10)=0,INDEX(Engine_Grid,150+$AB10,$AD10+1)=0),0,INDEX(Engine_Grid,150+$AB10,$AD10)*(1-$AE10)+INDEX(Engine_Grid,150+$AB10,$AD10+1)*$AE10)))*IF(N($D10)<1,1,$D10)) -> 2.0856693 | AK10: =IF(N($F10)<=0,0,$F10/100*IF(OR($AB10="",$AC10="",N($AC10)<1,N($AC10)>24),0,IF($AE10=0,INDEX(Engine_Grid,225+$AB10,$AD10),IF(OR($AD10>=24,INDEX(Engine_Grid,225+$AB10,$AD10)=0,INDEX(Engine_Grid,225+$AB10,$AD10+1)=0),0,INDEX(Engine_Grid,225+$AB10,$AD10)*(1-$AE10)+INDEX(Engine_Grid,225+$AB10,$AD10+1)*$AE10)))*IF(N($D10)<1,1,$D10)) -> 1.8777953
A11: 2 | B11: Back pocket attach | C11: 301 Lockstitch | D11: 2 | E11: 11 | F11: 36 | G11: =IF($AB11="","",IF(INDEX(Lib_Basis,$AB11)="Piece","pcs","cm")) -> cm | H11: =IF(OR($AB11="",$AC11="",N($AC11)<1,N($AC11)>24),0,IF($AE11=0,INDEX(Engine_Grid,(WeightIdx-1)*75+$AB11,$AD11),IF(OR($AD11>=24,INDEX(Engine_Grid,(WeightIdx-1)*75+$AB11,$AD11)=0,INDEX(Engine_Grid,(WeightIdx-1)*75+$AB11,$AD11+1)=0),0,INDEX(Engine_Grid,(WeightIdx-1)*75+$AB11,$AD11)*(1-$AE11)+INDEX(Engine_Grid,(WeightIdx-1)*75+$AB11,$AD11+1)*$AE11))) -> 3.6456693 | I11: =IF(OR($H11=0,N($F11)<=0),0,$F11/100*$H11*IF(N($D11)<1,1,$D11)) -> 2.6248819 | J11: =IF($AB11="","",INDEX(Lib_Needle,$AB11)) -> 0.51 | K11: =IF($AB11="","",INDEX(Lib_Bobbin,$AB11)) -> 0.49 | L11: =IF($AB11="","",INDEX(Lib_Looper,$AB11)) -> 0 | M11: =IF($AB11="","",INDEX(Lib_Cover,$AB11)) -> 0 | N11: Tex 40 Spun Poly – Khaki (needle) | O11: =IF($I11=0,0,IF($AF11="Y",$I11*$J11/IF(N($D11)<1,1,$D11),$I11*$J11)) -> 0.66934488 | P11: Tex 40 Spun Poly – Khaki (needle) | Q11: =IF(AND($I11>0,$AF11="Y",IF(N($D11)<1,1,$D11)>=2),$I11*$J11/IF(N($D11)<1,1,$D11),0) -> 0.66934488 | S11: =IF(AND($I11>0,$AF11="Y",IF(N($D11)<1,1,$D11)>=3),$I11*$J11/IF(N($D11)<1,1,$D11),0) -> 0 | T11: Tex 60 Spun Poly – Khaki (bobbin / looper) | U11: =IF($I11=0,0,$I11*$K11) -> 1.2861921 | W11: =IF($I11=0,0,$I11*$L11) -> 0 | Y11: =IF($I11=0,0,$I11*$M11) -> 0 | Z11: =IF($N11="",$O11,0)+IF($P11="",$Q11,0)+IF($R11="",$S11,0)+IF($T11="",$U11,0)+IF($V11="",$W11,0)+IF($X11="",$Y11,0)+IF(AND($AF11="Y",IF(N($D11)<1,1,$D11)>3),$I11*$J11*(IF(N($D11)<1,1,$D11)-3)/IF(N($D11)<1,1,$D11),0) -> 0 | AA11: =IF(AND($C11="",N($F11)=0),"",IF($C11="","⚠ Select a stitch type",IF($AB11="","⚠ Stitch not in library",IF(N($F11)<=0,"⚠ Enter "&IF($G11="pcs","quantity","seam length (cm)"),IF(AND($G11="cm",N($E11)<=0),"⚠ Enter SPI",IF($H11=0,"⚠ No factor at SPI "&$E11&" – valid "&INDEX(Lib_MinSPI,$AB11)&"–"&INDEX(Lib_MaxSPI,$AB11),IF(AND($AF11="Y",IF(N($D11)<1,1,$D11)>3),"⚠ More than 3 rows – thread for extra rows not allocated",IF($Z11>0.00001,"⚠ Assign threads ("&TEXT($Z11,"0.00")&" m unassigned)","✔ OK")))))))) -> ✔ OK | AB11: =IF($C11="","",IFERROR(MATCH($C11,Lib_Names,0),"")) -> 7 | AC11: =IF($AB11="","",IF(INDEX(Lib_Basis,$AB11)="Piece",1,N($E11))) -> 11 | AD11: =IF($AC11="","",INT($AC11)) -> 11 | AE11: =IF($AC11="","",$AC11-$AD11) -> 0 | AF11: =IF($AB11="","",INDEX(Lib_Multi,$AB11)) -> Y | AG11: =IF($AB11="","",INDEX(Lib_Cat,$AB11)) -> Lockstitch / zigzag | AH11: =IF(N($F11)<=0,0,$F11/100*IF(OR($AB11="",$AC11="",N($AC11)<1,N($AC11)>24),0,IF($AE11=0,INDEX(Engine_Grid,0+$AB11,$AD11),IF(OR($AD11>=24,INDEX(Engine_Grid,0+$AB11,$AD11)=0,INDEX(Engine_Grid,0+$AB11,$AD11+1)=0),0,INDEX(Engine_Grid,0+$AB11,$AD11)*(1-$AE11)+INDEX(Engine_Grid,0+$AB11,$AD11+1)*$AE11)))*IF(N($D11)<1,1,$D11)) -> 2.1883465 | AI11: =IF(N($F11)<=0,0,$F11/100*IF(OR($AB11="",$AC11="",N($AC11)<1,N($AC11)>24),0,IF($AE11=0,INDEX(Engine_Grid,75+$AB11,$AD11),IF(OR($AD11>=24,INDEX(Engine_Grid,75+$AB11,$AD11)=0,INDEX(Engine_Grid,75+$AB11,$AD11+1)=0),0,INDEX(Engine_Grid,75+$AB11,$AD11)*(1-$AE11)+INDEX(Engine_Grid,75+$AB11,$AD11+1)*$AE11)))*IF(N($D11)<1,1,$D11)) -> 2.6248819 | AJ11: =IF(N($F11)<=0,0,$F11/100*IF(OR($AB11="",$AC11="",N($AC11)<1,N($AC11)>24),0,IF($AE11=0,INDEX(Engine_Grid,150+$AB11,$AD11),IF(OR($AD11>=24,INDEX(Engine_Grid,150+$AB11,$AD11)=0,INDEX(Engine_Grid,150+$AB11,$AD11+1)=0),0,INDEX(Engine_Grid,150+$AB11,$AD11)*(1-$AE11)+INDEX(Engine_Grid,150+$AB11,$AD11+1)*$AE11)))*IF(N($D11)<1,1,$D11)) -> 3.2485039 | AK11: =IF(N($F11)<=0,0,$F11/100*IF(OR($AB11="",$AC11="",N($AC11)<1,N($AC11)>24),0,IF($AE11=0,INDEX(Engine_Grid,225+$AB11,$AD11),IF(OR($AD11>=24,INDEX(Engine_Grid,225+$AB11,$AD11)=0,INDEX(Engine_Grid,225+$AB11,$AD11+1)=0),0,INDEX(Engine_Grid,225+$AB11,$AD11)*(1-$AE11)+INDEX(Engine_Grid,225+$AB11,$AD11+1)*$AE11)))*IF(N($D11)<1,1,$D11)) -> 2.9366929
A12: 3 | B12: Side seam – overedge | C12: 504 1/4" 1 Ndl Overedge | D12: 1 | E12: 10 | F12: 210 | G12: =IF($AB12="","",IF(INDEX(Lib_Basis,$AB12)="Piece","pcs","cm")) -> cm | H12: =IF(OR($AB12="",$AC12="",N($AC12)<1,N($AC12)>24),0,IF($AE12=0,INDEX(Engine_Grid,(WeightIdx-1)*75+$AB12,$AD12),IF(OR($AD12>=24,INDEX(Engine_Grid,(WeightIdx-1)*75+$AB12,$AD12)=0,INDEX(Engine_Grid,(WeightIdx-1)*75+$AB12,$AD12+1)=0),0,INDEX(Engine_Grid,(WeightIdx-1)*75+$AB12,$AD12)*(1-$AE12)+INDEX(Engine_Grid,(WeightIdx-1)*75+$AB12,$AD12+1)*$AE12))) -> 17.992126 | I12: =IF(OR($H12=0,N($F12)<=0),0,$F12/100*$H12*IF(N($D12)<1,1,$D12)) -> 37.783465 | J12: =IF($AB12="","",INDEX(Lib_Needle,$AB12)) -> 0.22 | K12: =IF($AB12="","",INDEX(Lib_Bobbin,$AB12)) -> 0 | L12: =IF($AB12="","",INDEX(Lib_Looper,$AB12)) -> 0.78 | M12: =IF($AB12="","",INDEX(Lib_Cover,$AB12)) -> 0 | N12: Tex 40 Spun Poly – Khaki (needle) | O12: =IF($I12=0,0,IF($AF12="Y",$I12*$J12/IF(N($D12)<1,1,$D12),$I12*$J12)) -> 8.3123622 | Q12: =IF(AND($I12>0,$AF12="Y",IF(N($D12)<1,1,$D12)>=2),$I12*$J12/IF(N($D12)<1,1,$D12),0) -> 0 | S12: =IF(AND($I12>0,$AF12="Y",IF(N($D12)<1,1,$D12)>=3),$I12*$J12/IF(N($D12)<1,1,$D12),0) -> 0 | U12: =IF($I12=0,0,$I12*$K12) -> 0 | V12: Tex 60 Spun Poly – Khaki (bobbin / looper) | W12: =IF($I12=0,0,$I12*$L12) -> 29.471102 | Y12: =IF($I12=0,0,$I12*$M12) -> 0 | Z12: =IF($N12="",$O12,0)+IF($P12="",$Q12,0)+IF($R12="",$S12,0)+IF($T12="",$U12,0)+IF($V12="",$W12,0)+IF($X12="",$Y12,0)+IF(AND($AF12="Y",IF(N($D12)<1,1,$D12)>3),$I12*$J12*(IF(N($D12)<1,1,$D12)-3)/IF(N($D12)<1,1,$D12),0) -> 0 | AA12: =IF(AND($C12="",N($F12)=0),"",IF($C12="","⚠ Select a stitch type",IF($AB12="","⚠ Stitch not in library",IF(N($F12)<=0,"⚠ Enter "&IF($G12="pcs","quantity","seam length (cm)"),IF(AND($G12="cm",N($E12)<=0),"⚠ Enter SPI",IF($H12=0,"⚠ No factor at SPI "&$E12&" – valid "&INDEX(Lib_MinSPI,$AB12)&"–"&INDEX(Lib_MaxSPI,$AB12),IF(AND($AF12="Y",IF(N($D12)<1,1,$D12)>3),"⚠ More than 3 rows – thread for extra rows not allocated",IF($Z12>0.00001,"⚠ Assign threads ("&TEXT($Z12,"0.00")&" m unassigned)","✔ OK")))))))) -> ✔ OK | AB12: =IF($C12="","",IFERROR(MATCH($C12,Lib_Names,0),"")) -> 27 | AC12: =IF($AB12="","",IF(INDEX(Lib_Basis,$AB12)="Piece",1,N($E12))) -> 10 | AD12: =IF($AC12="","",INT($AC12)) -> 10 | AE12: =IF($AC12="","",$AC12-$AD12) -> 0 | AF12: =IF($AB12="","",INDEX(Lib_Multi,$AB12)) -> Y | AG12: =IF($AB12="","",INDEX(Lib_Cat,$AB12)) -> Overlock / overedge | AH12: =IF(N($F12)<=0,0,$F12/100*IF(OR($AB12="",$AC12="",N($AC12)<1,N($AC12)>24),0,IF($AE12=0,INDEX(Engine_Grid,0+$AB12,$AD12),IF(OR($AD12>=24,INDEX(Engine_Grid,0+$AB12,$AD12)=0,INDEX(Engine_Grid,0+$AB12,$AD12+1)=0),0,INDEX(Engine_Grid,0+$AB12,$AD12)*(1-$AE12)+INDEX(Engine_Grid,0+$AB12,$AD12+1)*$AE12)))*IF(N($D12)<1,1,$D12)) -> 35.468504 | AI12: =IF(N($F12)<=0,0,$F12/100*IF(OR($AB12="",$AC12="",N($AC12)<1,N($AC12)>24),0,IF($AE12=0,INDEX(Engine_Grid,75+$AB12,$AD12),IF(OR($AD12>=24,INDEX(Engine_Grid,75+$AB12,$AD12)=0,INDEX(Engine_Grid,75+$AB12,$AD12+1)=0),0,INDEX(Engine_Grid,75+$AB12,$AD12)*(1-$AE12)+INDEX(Engine_Grid,75+$AB12,$AD12+1)*$AE12)))*IF(N($D12)<1,1,$D12)) -> 37.783465 | AJ12: =IF(N($F12)<=0,0,$F12/100*IF(OR($AB12="",$AC12="",N($AC12)<1,N($AC12)>24),0,IF($AE12=0,INDEX(Engine_Grid,150+$AB12,$AD12),IF(OR($AD12>=24,INDEX(Engine_Grid,150+$AB12,$AD12)=0,INDEX(Engine_Grid,150+$AB12,$AD12+1)=0),0,INDEX(Engine_Grid,150+$AB12,$AD12)*(1-$AE12)+INDEX(Engine_Grid,150+$AB12,$AD12+1)*$AE12)))*IF(N($D12)<1,1,$D12)) -> 41.090551 | AK12: =IF(N($F12)<=0,0,$F12/100*IF(OR($AB12="",$AC12="",N($AC12)<1,N($AC12)>24),0,IF($AE12=0,INDEX(Engine_Grid,225+$AB12,$AD12),IF(OR($AD12>=24,INDEX(Engine_Grid,225+$AB12,$AD12)=0,INDEX(Engine_Grid,225+$AB12,$AD12+1)=0),0,INDEX(Engine_Grid,225+$AB12,$AD12)*(1-$AE12)+INDEX(Engine_Grid,225+$AB12,$AD12+1)*$AE12)))*IF(N($D12)<1,1,$D12)) -> 39.437008
A13: 4 | B13: Inseam | C13: 401 Chainstitch | D13: 1 | E13: 10 | F13: 150 | G13: =IF($AB13="","",IF(INDEX(Lib_Basis,$AB13)="Piece","pcs","cm")) -> cm | H13: =IF(OR($AB13="",$AC13="",N($AC13)<1,N($AC13)>24),0,IF($AE13=0,INDEX(Engine_Grid,(WeightIdx-1)*75+$AB13,$AD13),IF(OR($AD13>=24,INDEX(Engine_Grid,(WeightIdx-1)*75+$AB13,$AD13)=0,INDEX(Engine_Grid,(WeightIdx-1)*75+$AB13,$AD13+1)=0),0,INDEX(Engine_Grid,(WeightIdx-1)*75+$AB13,$AD13)*(1-$AE13)+INDEX(Engine_Grid,(WeightIdx-1)*75+$AB13,$AD13+1)*$AE13))) -> 5.496063 | I13: =IF(OR($H13=0,N($F13)<=0),0,$F13/100*$H13*IF(N($D13)<1,1,$D13)) -> 8.2440945 | J13: =IF($AB13="","",INDEX(Lib_Needle,$AB13)) -> 0.55 | K13: =IF($AB13="","",INDEX(Lib_Bobbin,$AB13)) -> 0 | L13: =IF($AB13="","",INDEX(Lib_Looper,$AB13)) -> 0.45 | M13: =IF($AB13="","",INDEX(Lib_Cover,$AB13)) -> 0 | N13: Tex 40 Spun Poly – Khaki (needle) | O13: =IF($I13=0,0,IF($AF13="Y",$I13*$J13/IF(N($D13)<1,1,$D13),$I13*$J13)) -> 4.534252 | Q13: =IF(AND($I13>0,$AF13="Y",IF(N($D13)<1,1,$D13)>=2),$I13*$J13/IF(N($D13)<1,1,$D13),0) -> 0 | S13: =IF(AND($I13>0,$AF13="Y",IF(N($D13)<1,1,$D13)>=3),$I13*$J13/IF(N($D13)<1,1,$D13),0) -> 0 | U13: =IF($I13=0,0,$I13*$K13) -> 0 | V13: Tex 60 Spun Poly – Khaki (bobbin / looper) | W13: =IF($I13=0,0,$I13*$L13) -> 3.7098425 | Y13: =IF($I13=0,0,$I13*$M13) -> 0 | Z13: =IF($N13="",$O13,0)+IF($P13="",$Q13,0)+IF($R13="",$S13,0)+IF($T13="",$U13,0)+IF($V13="",$W13,0)+IF($X13="",$Y13,0)+IF(AND($AF13="Y",IF(N($D13)<1,1,$D13)>3),$I13*$J13*(IF(N($D13)<1,1,$D13)-3)/IF(N($D13)<1,1,$D13),0) -> 0 | AA13: =IF(AND($C13="",N($F13)=0),"",IF($C13="","⚠ Select a stitch type",IF($AB13="","⚠ Stitch not in library",IF(N($F13)<=0,"⚠ Enter "&IF($G13="pcs","quantity","seam length (cm)"),IF(AND($G13="cm",N($E13)<=0),"⚠ Enter SPI",IF($H13=0,"⚠ No factor at SPI "&$E13&" – valid "&INDEX(Lib_MinSPI,$AB13)&"–"&INDEX(Lib_MaxSPI,$AB13),IF(AND($AF13="Y",IF(N($D13)<1,1,$D13)>3),"⚠ More than 3 rows – thread for extra rows not allocated",IF($Z13>0.00001,"⚠ Assign threads ("&TEXT($Z13,"0.00")&" m unassigned)","✔ OK")))))))) -> ✔ OK | AB13: =IF($C13="","",IFERROR(MATCH($C13,Lib_Names,0),"")) -> 14 | AC13: =IF($AB13="","",IF(INDEX(Lib_Basis,$AB13)="Piece",1,N($E13))) -> 10 | AD13: =IF($AC13="","",INT($AC13)) -> 10 | AE13: =IF($AC13="","",$AC13-$AD13) -> 0 | AF13: =IF($AB13="","",INDEX(Lib_Multi,$AB13)) -> Y | AG13: =IF($AB13="","",INDEX(Lib_Cat,$AB13)) -> Chainstitch | AH13: =IF(N($F13)<=0,0,$F13/100*IF(OR($AB13="",$AC13="",N($AC13)<1,N($AC13)>24),0,IF($AE13=0,INDEX(Engine_Grid,0+$AB13,$AD13),IF(OR($AD13>=24,INDEX(Engine_Grid,0+$AB13,$AD13)=0,INDEX(Engine_Grid,0+$AB13,$AD13+1)=0),0,INDEX(Engine_Grid,0+$AB13,$AD13)*(1-$AE13)+INDEX(Engine_Grid,0+$AB13,$AD13+1)*$AE13)))*IF(N($D13)<1,1,$D13)) -> 7.4173228 | AI13: =IF(N($F13)<=0,0,$F13/100*IF(OR($AB13="",$AC13="",N($AC13)<1,N($AC13)>24),0,IF($AE13=0,INDEX(Engine_Grid,75+$AB13,$AD13),IF(OR($AD13>=24,INDEX(Engine_Grid,75+$AB13,$AD13)=0,INDEX(Engine_Grid,75+$AB13,$AD13+1)=0),0,INDEX(Engine_Grid,75+$AB13,$AD13)*(1-$AE13)+INDEX(Engine_Grid,75+$AB13,$AD13+1)*$AE13)))*IF(N($D13)<1,1,$D13)) -> 8.2440945 | AJ13: =IF(N($F13)<=0,0,$F13/100*IF(OR($AB13="",$AC13="",N($AC13)<1,N($AC13)>24),0,IF($AE13=0,INDEX(Engine_Grid,150+$AB13,$AD13),IF(OR($AD13>=24,INDEX(Engine_Grid,150+$AB13,$AD13)=0,INDEX(Engine_Grid,150+$AB13,$AD13+1)=0),0,INDEX(Engine_Grid,150+$AB13,$AD13)*(1-$AE13)+INDEX(Engine_Grid,150+$AB13,$AD13+1)*$AE13)))*IF(N($D13)<1,1,$D13)) -> 9.4251969 | AK13: =IF(N($F13)<=0,0,$F13/100*IF(OR($AB13="",$AC13="",N($AC13)<1,N($AC13)>24),0,IF($AE13=0,INDEX(Engine_Grid,225+$AB13,$AD13),IF(OR($AD13>=24,INDEX(Engine_Grid,225+$AB13,$AD13)=0,INDEX(Engine_Grid,225+$AB13,$AD13+1)=0),0,INDEX(Engine_Grid,225+$AB13,$AD13)*(1-$AE13)+INDEX(Engine_Grid,225+$AB13,$AD13+1)*$AE13)))*IF(N($D13)<1,1,$D13)) -> 8.8346457
A14: 5 | B14: Waistband attach | C14: 301 Lockstitch | D14: 2 | E14: 12 | F14: 96 | G14: =IF($AB14="","",IF(INDEX(Lib_Basis,$AB14)="Piece","pcs","cm")) -> cm | H14: =IF(OR($AB14="",$AC14="",N($AC14)<1,N($AC14)>24),0,IF($AE14=0,INDEX(Engine_Grid,(WeightIdx-1)*75+$AB14,$AD14),IF(OR($AD14>=24,INDEX(Engine_Grid,(WeightIdx-1)*75+$AB14,$AD14)=0,INDEX(Engine_Grid,(WeightIdx-1)*75+$AB14,$AD14+1)=0),0,INDEX(Engine_Grid,(WeightIdx-1)*75+$AB14,$AD14)*(1-$AE14)+INDEX(Engine_Grid,(WeightIdx-1)*75+$AB14,$AD14+1)*$AE14))) -> 3.7952756 | I14: =IF(OR($H14=0,N($F14)<=0),0,$F14/100*$H14*IF(N($D14)<1,1,$D14)) -> 7.2869291 | J14: =IF($AB14="","",INDEX(Lib_Needle,$AB14)) -> 0.51 | K14: =IF($AB14="","",INDEX(Lib_Bobbin,$AB14)) -> 0.49 | L14: =IF($AB14="","",INDEX(Lib_Looper,$AB14)) -> 0 | M14: =IF($AB14="","",INDEX(Lib_Cover,$AB14)) -> 0 | N14: Tex 40 Spun Poly – Khaki (needle) | O14: =IF($I14=0,0,IF($AF14="Y",$I14*$J14/IF(N($D14)<1,1,$D14),$I14*$J14)) -> 1.8581669 | P14: Tex 40 Spun Poly – Khaki (needle) | Q14: =IF(AND($I14>0,$AF14="Y",IF(N($D14)<1,1,$D14)>=2),$I14*$J14/IF(N($D14)<1,1,$D14),0) -> 1.8581669 | S14: =IF(AND($I14>0,$AF14="Y",IF(N($D14)<1,1,$D14)>=3),$I14*$J14/IF(N($D14)<1,1,$D14),0) -> 0 | T14: Tex 60 Spun Poly – Khaki (bobbin / looper) | U14: =IF($I14=0,0,$I14*$K14) -> 3.5705953 | W14: =IF($I14=0,0,$I14*$L14) -> 0 | Y14: =IF($I14=0,0,$I14*$M14) -> 0 | Z14: =IF($N14="",$O14,0)+IF($P14="",$Q14,0)+IF($R14="",$S14,0)+IF($T14="",$U14,0)+IF($V14="",$W14,0)+IF($X14="",$Y14,0)+IF(AND($AF14="Y",IF(N($D14)<1,1,$D14)>3),$I14*$J14*(IF(N($D14)<1,1,$D14)-3)/IF(N($D14)<1,1,$D14),0) -> 0 | AA14: =IF(AND($C14="",N($F14)=0),"",IF($C14="","⚠ Select a stitch type",IF($AB14="","⚠ Stitch not in library",IF(N($F14)<=0,"⚠ Enter "&IF($G14="pcs","quantity","seam length (cm)"),IF(AND($G14="cm",N($E14)<=0),"⚠ Enter SPI",IF($H14=0,"⚠ No factor at SPI "&$E14&" – valid "&INDEX(Lib_MinSPI,$AB14)&"–"&INDEX(Lib_MaxSPI,$AB14),IF(AND($AF14="Y",IF(N($D14)<1,1,$D14)>3),"⚠ More than 3 rows – thread for extra rows not allocated",IF($Z14>0.00001,"⚠ Assign threads ("&TEXT($Z14,"0.00")&" m unassigned)","✔ OK")))))))) -> ✔ OK | AB14: =IF($C14="","",IFERROR(MATCH($C14,Lib_Names,0),"")) -> 7 | AC14: =IF($AB14="","",IF(INDEX(Lib_Basis,$AB14)="Piece",1,N($E14))) -> 12 | AD14: =IF($AC14="","",INT($AC14)) -> 12 | AE14: =IF($AC14="","",$AC14-$AD14) -> 0 | AF14: =IF($AB14="","",INDEX(Lib_Multi,$AB14)) -> Y | AG14: =IF($AB14="","",INDEX(Lib_Cat,$AB14)) -> Lockstitch / zigzag | AH14: =IF(N($F14)<=0,0,$F14/100*IF(OR($AB14="",$AC14="",N($AC14)<1,N($AC14)>24),0,IF($AE14=0,INDEX(Engine_Grid,0+$AB14,$AD14),IF(OR($AD14>=24,INDEX(Engine_Grid,0+$AB14,$AD14)=0,INDEX(Engine_Grid,0+$AB14,$AD14+1)=0),0,INDEX(Engine_Grid,0+$AB14,$AD14)*(1-$AE14)+INDEX(Engine_Grid,0+$AB14,$AD14+1)*$AE14)))*IF(N($D14)<1,1,$D14)) -> 6.0170079 | AI14: =IF(N($F14)<=0,0,$F14/100*IF(OR($AB14="",$AC14="",N($AC14)<1,N($AC14)>24),0,IF($AE14=0,INDEX(Engine_Grid,75+$AB14,$AD14),IF(OR($AD14>=24,INDEX(Engine_Grid,75+$AB14,$AD14)=0,INDEX(Engine_Grid,75+$AB14,$AD14+1)=0),0,INDEX(Engine_Grid,75+$AB14,$AD14)*(1-$AE14)+INDEX(Engine_Grid,75+$AB14,$AD14+1)*$AE14)))*IF(N($D14)<1,1,$D14)) -> 7.2869291 | AJ14: =IF(N($F14)<=0,0,$F14/100*IF(OR($AB14="",$AC14="",N($AC14)<1,N($AC14)>24),0,IF($AE14=0,INDEX(Engine_Grid,150+$AB14,$AD14),IF(OR($AD14>=24,INDEX(Engine_Grid,150+$AB14,$AD14)=0,INDEX(Engine_Grid,150+$AB14,$AD14+1)=0),0,INDEX(Engine_Grid,150+$AB14,$AD14)*(1-$AE14)+INDEX(Engine_Grid,150+$AB14,$AD14+1)*$AE14)))*IF(N($D14)<1,1,$D14)) -> 9.1011024 | AK14: =IF(N($F14)<=0,0,$F14/100*IF(OR($AB14="",$AC14="",N($AC14)<1,N($AC14)>24),0,IF($AE14=0,INDEX(Engine_Grid,225+$AB14,$AD14),IF(OR($AD14>=24,INDEX(Engine_Grid,225+$AB14,$AD14)=0,INDEX(Engine_Grid,225+$AB14,$AD14+1)=0),0,INDEX(Engine_Grid,225+$AB14,$AD14)*(1-$AE14)+INDEX(Engine_Grid,225+$AB14,$AD14+1)*$AE14)))*IF(N($D14)<1,1,$D14)) -> 8.1940157
A15: 6 | B15: Hem – blind stitch | C15: 103 Blindstitch | D15: 1 | E15: 6 | F15: 110 | G15: =IF($AB15="","",IF(INDEX(Lib_Basis,$AB15)="Piece","pcs","cm")) -> cm | H15: =IF(OR($AB15="",$AC15="",N($AC15)<1,N($AC15)>24),0,IF($AE15=0,INDEX(Engine_Grid,(WeightIdx-1)*75+$AB15,$AD15),IF(OR($AD15>=24,INDEX(Engine_Grid,(WeightIdx-1)*75+$AB15,$AD15)=0,INDEX(Engine_Grid,(WeightIdx-1)*75+$AB15,$AD15+1)=0),0,INDEX(Engine_Grid,(WeightIdx-1)*75+$AB15,$AD15)*(1-$AE15)+INDEX(Engine_Grid,(WeightIdx-1)*75+$AB15,$AD15+1)*$AE15))) -> 3.84 | I15: =IF(OR($H15=0,N($F15)<=0),0,$F15/100*$H15*IF(N($D15)<1,1,$D15)) -> 4.224 | J15: =IF($AB15="","",INDEX(Lib_Needle,$AB15)) -> 1 | K15: =IF($AB15="","",INDEX(Lib_Bobbin,$AB15)) -> 0 | L15: =IF($AB15="","",INDEX(Lib_Looper,$AB15)) -> 0 | M15: =IF($AB15="","",INDEX(Lib_Cover,$AB15)) -> 0 | N15: Tex 40 Spun Poly – Khaki (needle) | O15: =IF($I15=0,0,IF($AF15="Y",$I15*$J15/IF(N($D15)<1,1,$D15),$I15*$J15)) -> 4.224 | Q15: =IF(AND($I15>0,$AF15="Y",IF(N($D15)<1,1,$D15)>=2),$I15*$J15/IF(N($D15)<1,1,$D15),0) -> 0 | S15: =IF(AND($I15>0,$AF15="Y",IF(N($D15)<1,1,$D15)>=3),$I15*$J15/IF(N($D15)<1,1,$D15),0) -> 0 | U15: =IF($I15=0,0,$I15*$K15) -> 0 | W15: =IF($I15=0,0,$I15*$L15) -> 0 | Y15: =IF($I15=0,0,$I15*$M15) -> 0 | Z15: =IF($N15="",$O15,0)+IF($P15="",$Q15,0)+IF($R15="",$S15,0)+IF($T15="",$U15,0)+IF($V15="",$W15,0)+IF($X15="",$Y15,0)+IF(AND($AF15="Y",IF(N($D15)<1,1,$D15)>3),$I15*$J15*(IF(N($D15)<1,1,$D15)-3)/IF(N($D15)<1,1,$D15),0) -> 0 | AA15: =IF(AND($C15="",N($F15)=0),"",IF($C15="","⚠ Select a stitch type",IF($AB15="","⚠ Stitch not in library",IF(N($F15)<=0,"⚠ Enter "&IF($G15="pcs","quantity","seam length (cm)"),IF(AND($G15="cm",N($E15)<=0),"⚠ Enter SPI",IF($H15=0,"⚠ No factor at SPI "&$E15&" – valid "&INDEX(Lib_MinSPI,$AB15)&"–"&INDEX(Lib_MaxSPI,$AB15),IF(AND($AF15="Y",IF(N($D15)<1,1,$D15)>3),"⚠ More than 3 rows – thread for extra rows not allocated",IF($Z15>0.00001,"⚠ Assign threads ("&TEXT($Z15,"0.00")&" m unassigned)","✔ OK")))))))) -> ✔ OK | AB15: =IF($C15="","",IFERROR(MATCH($C15,Lib_Names,0),"")) -> 1 | AC15: =IF($AB15="","",IF(INDEX(Lib_Basis,$AB15)="Piece",1,N($E15))) -> 6 | AD15: =IF($AC15="","",INT($AC15)) -> 6 | AE15: =IF($AC15="","",$AC15-$AD15) -> 0 | AF15: =IF($AB15="","",INDEX(Lib_Multi,$AB15)) -> Y | AG15: =IF($AB15="","",INDEX(Lib_Cat,$AB15)) -> Blind / saddle stitch | AH15: =IF(N($F15)<=0,0,$F15/100*IF(OR($AB15="",$AC15="",N($AC15)<1,N($AC15)>24),0,IF($AE15=0,INDEX(Engine_Grid,0+$AB15,$AD15),IF(OR($AD15>=24,INDEX(Engine_Grid,0+$AB15,$AD15)=0,INDEX(Engine_Grid,0+$AB15,$AD15+1)=0),0,INDEX(Engine_Grid,0+$AB15,$AD15)*(1-$AE15)+INDEX(Engine_Grid,0+$AB15,$AD15+1)*$AE15)))*IF(N($D15)<1,1,$D15)) -> 4.224 | AI15: =IF(N($F15)<=0,0,$F15/100*IF(OR($AB15="",$AC15="",N($AC15)<1,N($AC15)>24),0,IF($AE15=0,INDEX(Engine_Grid,75+$AB15,$AD15),IF(OR($AD15>=24,INDEX(Engine_Grid,75+$AB15,$AD15)=0,INDEX(Engine_Grid,75+$AB15,$AD15+1)=0),0,INDEX(Engine_Grid,75+$AB15,$AD15)*(1-$AE15)+INDEX(Engine_Grid,75+$AB15,$AD15+1)*$AE15)))*IF(N($D15)<1,1,$D15)) -> 4.224 | AJ15: =IF(N($F15)<=0,0,$F15/100*IF(OR($AB15="",$AC15="",N($AC15)<1,N($AC15)>24),0,IF($AE15=0,INDEX(Engine_Grid,150+$AB15,$AD15),IF(OR($AD15>=24,INDEX(Engine_Grid,150+$AB15,$AD15)=0,INDEX(Engine_Grid,150+$AB15,$AD15+1)=0),0,INDEX(Engine_Grid,150+$AB15,$AD15)*(1-$AE15)+INDEX(Engine_Grid,150+$AB15,$AD15+1)*$AE15)))*IF(N($D15)<1,1,$D15)) -> 4.224 | AK15: =IF(N($F15)<=0,0,$F15/100*IF(OR($AB15="",$AC15="",N($AC15)<1,N($AC15)>24),0,IF($AE15=0,INDEX(Engine_Grid,225+$AB15,$AD15),IF(OR($AD15>=24,INDEX(Engine_Grid,225+$AB15,$AD15)=0,INDEX(Engine_Grid,225+$AB15,$AD15+1)=0),0,INDEX(Engine_Grid,225+$AB15,$AD15)*(1-$AE15)+INDEX(Engine_Grid,225+$AB15,$AD15+1)*$AE15)))*IF(N($D15)<1,1,$D15)) -> 4.224
A16: 7 | B16: Belt-loop bartacks (7 pcs) | C16: Bartack 3/8" | F16: 7 | G16: =IF($AB16="","",IF(INDEX(Lib_Basis,$AB16)="Piece","pcs","cm")) -> pcs | H16: =IF(OR($AB16="",$AC16="",N($AC16)<1,N($AC16)>24),0,IF($AE16=0,INDEX(Engine_Grid,(WeightIdx-1)*75+$AB16,$AD16),IF(OR($AD16>=24,INDEX(Engine_Grid,(WeightIdx-1)*75+$AB16,$AD16)=0,INDEX(Engine_Grid,(WeightIdx-1)*75+$AB16,$AD16+1)=0),0,INDEX(Engine_Grid,(WeightIdx-1)*75+$AB16,$AD16)*(1-$AE16)+INDEX(Engine_Grid,(WeightIdx-1)*75+$AB16,$AD16+1)*$AE16))) -> 14 | I16: =IF(OR($H16=0,N($F16)<=0),0,$F16/100*$H16*IF(N($D16)<1,1,$D16)) -> 0.98 | J16: =IF($AB16="","",INDEX(Lib_Needle,$AB16)) -> 0.77 | K16: =IF($AB16="","",INDEX(Lib_Bobbin,$AB16)) -> 0.23 | L16: =IF($AB16="","",INDEX(Lib_Looper,$AB16)) -> 0 | M16: =IF($AB16="","",INDEX(Lib_Cover,$AB16)) -> 0 | N16: Tex 27 Core Poly – Khaki (bartack / buttonhole) | O16: =IF($I16=0,0,IF($AF16="Y",$I16*$J16/IF(N($D16)<1,1,$D16),$I16*$J16)) -> 0.7546 | Q16: =IF(AND($I16>0,$AF16="Y",IF(N($D16)<1,1,$D16)>=2),$I16*$J16/IF(N($D16)<1,1,$D16),0) -> 0 | S16: =IF(AND($I16>0,$AF16="Y",IF(N($D16)<1,1,$D16)>=3),$I16*$J16/IF(N($D16)<1,1,$D16),0) -> 0 | T16: Tex 27 Core Poly – Khaki (bartack / buttonhole) | U16: =IF($I16=0,0,$I16*$K16) -> 0.2254 | W16: =IF($I16=0,0,$I16*$L16) -> 0 | Y16: =IF($I16=0,0,$I16*$M16) -> 0 | Z16: =IF($N16="",$O16,0)+IF($P16="",$Q16,0)+IF($R16="",$S16,0)+IF($T16="",$U16,0)+IF($V16="",$W16,0)+IF($X16="",$Y16,0)+IF(AND($AF16="Y",IF(N($D16)<1,1,$D16)>3),$I16*$J16*(IF(N($D16)<1,1,$D16)-3)/IF(N($D16)<1,1,$D16),0) -> 0 | AA16: =IF(AND($C16="",N($F16)=0),"",IF($C16="","⚠ Select a stitch type",IF($AB16="","⚠ Stitch not in library",IF(N($F16)<=0,"⚠ Enter "&IF($G16="pcs","quantity","seam length (cm)"),IF(AND($G16="cm",N($E16)<=0),"⚠ Enter SPI",IF($H16=0,"⚠ No factor at SPI "&$E16&" – valid "&INDEX(Lib_MinSPI,$AB16)&"–"&INDEX(Lib_MaxSPI,$AB16),IF(AND($AF16="Y",IF(N($D16)<1,1,$D16)>3),"⚠ More than 3 rows – thread for extra rows not allocated",IF($Z16>0.00001,"⚠ Assign threads ("&TEXT($Z16,"0.00")&" m unassigned)","✔ OK")))))))) -> ✔ OK | AB16: =IF($C16="","",IFERROR(MATCH($C16,Lib_Names,0),"")) -> 50 | AC16: =IF($AB16="","",IF(INDEX(Lib_Basis,$AB16)="Piece",1,N($E16))) -> 1 | AD16: =IF($AC16="","",INT($AC16)) -> 1 | AE16: =IF($AC16="","",$AC16-$AD16) -> 0 | AF16: =IF($AB16="","",INDEX(Lib_Multi,$AB16)) -> N | AG16: =IF($AB16="","",INDEX(Lib_Cat,$AB16)) -> Bartack | AH16: =IF(N($F16)<=0,0,$F16/100*IF(OR($AB16="",$AC16="",N($AC16)<1,N($AC16)>24),0,IF($AE16=0,INDEX(Engine_Grid,0+$AB16,$AD16),IF(OR($AD16>=24,INDEX(Engine_Grid,0+$AB16,$AD16)=0,INDEX(Engine_Grid,0+$AB16,$AD16+1)=0),0,INDEX(Engine_Grid,0+$AB16,$AD16)*(1-$AE16)+INDEX(Engine_Grid,0+$AB16,$AD16+1)*$AE16)))*IF(N($D16)<1,1,$D16)) -> 0.91 | AI16: =IF(N($F16)<=0,0,$F16/100*IF(OR($AB16="",$AC16="",N($AC16)<1,N($AC16)>24),0,IF($AE16=0,INDEX(Engine_Grid,75+$AB16,$AD16),IF(OR($AD16>=24,INDEX(Engine_Grid,75+$AB16,$AD16)=0,INDEX(Engine_Grid,75+$AB16,$AD16+1)=0),0,INDEX(Engine_Grid,75+$AB16,$AD16)*(1-$AE16)+INDEX(Engine_Grid,75+$AB16,$AD16+1)*$AE16)))*IF(N($D16)<1,1,$D16)) -> 0.98 | AJ16: =IF(N($F16)<=0,0,$F16/100*IF(OR($AB16="",$AC16="",N($AC16)<1,N($AC16)>24),0,IF($AE16=0,INDEX(Engine_Grid,150+$AB16,$AD16),IF(OR($AD16>=24,INDEX(Engine_Grid,150+$AB16,$AD16)=0,INDEX(Engine_Grid,150+$AB16,$AD16+1)=0),0,INDEX(Engine_Grid,150+$AB16,$AD16)*(1-$AE16)+INDEX(Engine_Grid,150+$AB16,$AD16+1)*$AE16)))*IF(N($D16)<1,1,$D16)) -> 1.4 | AK16: =IF(N($F16)<=0,0,$F16/100*IF(OR($AB16="",$AC16="",N($AC16)<1,N($AC16)>24),0,IF($AE16=0,INDEX(Engine_Grid,225+$AB16,$AD16),IF(OR($AD16>=24,INDEX(Engine_Grid,225+$AB16,$AD16)=0,INDEX(Engine_Grid,225+$AB16,$AD16+1)=0),0,INDEX(Engine_Grid,225+$AB16,$AD16)*(1-$AE16)+INDEX(Engine_Grid,225+$AB16,$AD16+1)*$AE16)))*IF(N($D16)<1,1,$D16)) -> 0.98
A17: 8 | B17: Waistband buttonhole | C17: BH 3/4" | F17: 1 | G17: =IF($AB17="","",IF(INDEX(Lib_Basis,$AB17)="Piece","pcs","cm")) -> pcs | H17: =IF(OR($AB17="",$AC17="",N($AC17)<1,N($AC17)>24),0,IF($AE17=0,INDEX(Engine_Grid,(WeightIdx-1)*75+$AB17,$AD17),IF(OR($AD17>=24,INDEX(Engine_Grid,(WeightIdx-1)*75+$AB17,$AD17)=0,INDEX(Engine_Grid,(WeightIdx-1)*75+$AB17,$AD17+1)=0),0,INDEX(Engine_Grid,(WeightIdx-1)*75+$AB17,$AD17)*(1-$AE17)+INDEX(Engine_Grid,(WeightIdx-1)*75+$AB17,$AD17+1)*$AE17))) -> 30 | I17: =IF(OR($H17=0,N($F17)<=0),0,$F17/100*$H17*IF(N($D17)<1,1,$D17)) -> 0.3 | J17: =IF($AB17="","",INDEX(Lib_Needle,$AB17)) -> 0.77 | K17: =IF($AB17="","",INDEX(Lib_Bobbin,$AB17)) -> 0.23 | L17: =IF($AB17="","",INDEX(Lib_Looper,$AB17)) -> 0 | M17: =IF($AB17="","",INDEX(Lib_Cover,$AB17)) -> 0 | N17: Tex 27 Core Poly – Khaki (bartack / buttonhole) | O17: =IF($I17=0,0,IF($AF17="Y",$I17*$J17/IF(N($D17)<1,1,$D17),$I17*$J17)) -> 0.231 | Q17: =IF(AND($I17>0,$AF17="Y",IF(N($D17)<1,1,$D17)>=2),$I17*$J17/IF(N($D17)<1,1,$D17),0) -> 0 | S17: =IF(AND($I17>0,$AF17="Y",IF(N($D17)<1,1,$D17)>=3),$I17*$J17/IF(N($D17)<1,1,$D17),0) -> 0 | T17: Tex 27 Core Poly – Khaki (bartack / buttonhole) | U17: =IF($I17=0,0,$I17*$K17) -> 0.069 | W17: =IF($I17=0,0,$I17*$L17) -> 0 | Y17: =IF($I17=0,0,$I17*$M17) -> 0 | Z17: =IF($N17="",$O17,0)+IF($P17="",$Q17,0)+IF($R17="",$S17,0)+IF($T17="",$U17,0)+IF($V17="",$W17,0)+IF($X17="",$Y17,0)+IF(AND($AF17="Y",IF(N($D17)<1,1,$D17)>3),$I17*$J17*(IF(N($D17)<1,1,$D17)-3)/IF(N($D17)<1,1,$D17),0) -> 0 | AA17: =IF(AND($C17="",N($F17)=0),"",IF($C17="","⚠ Select a stitch type",IF($AB17="","⚠ Stitch not in library",IF(N($F17)<=0,"⚠ Enter "&IF($G17="pcs","quantity","seam length (cm)"),IF(AND($G17="cm",N($E17)<=0),"⚠ Enter SPI",IF($H17=0,"⚠ No factor at SPI "&$E17&" – valid "&INDEX(Lib_MinSPI,$AB17)&"–"&INDEX(Lib_MaxSPI,$AB17),IF(AND($AF17="Y",IF(N($D17)<1,1,$D17)>3),"⚠ More than 3 rows – thread for extra rows not allocated",IF($Z17>0.00001,"⚠ Assign threads ("&TEXT($Z17,"0.00")&" m unassigned)","✔ OK")))))))) -> ✔ OK | AB17: =IF($C17="","",IFERROR(MATCH($C17,Lib_Names,0),"")) -> 57 | AC17: =IF($AB17="","",IF(INDEX(Lib_Basis,$AB17)="Piece",1,N($E17))) -> 1 | AD17: =IF($AC17="","",INT($AC17)) -> 1 | AE17: =IF($AC17="","",$AC17-$AD17) -> 0 | AF17: =IF($AB17="","",INDEX(Lib_Multi,$AB17)) -> N | AG17: =IF($AB17="","",INDEX(Lib_Cat,$AB17)) -> Buttonhole | AH17: =IF(N($F17)<=0,0,$F17/100*IF(OR($AB17="",$AC17="",N($AC17)<1,N($AC17)>24),0,IF($AE17=0,INDEX(Engine_Grid,0+$AB17,$AD17),IF(OR($AD17>=24,INDEX(Engine_Grid,0+$AB17,$AD17)=0,INDEX(Engine_Grid,0+$AB17,$AD17+1)=0),0,INDEX(Engine_Grid,0+$AB17,$AD17)*(1-$AE17)+INDEX(Engine_Grid,0+$AB17,$AD17+1)*$AE17)))*IF(N($D17)<1,1,$D17)) -> 0.3 | AI17: =IF(N($F17)<=0,0,$F17/100*IF(OR($AB17="",$AC17="",N($AC17)<1,N($AC17)>24),0,IF($AE17=0,INDEX(Engine_Grid,75+$AB17,$AD17),IF(OR($AD17>=24,INDEX(Engine_Grid,75+$AB17,$AD17)=0,INDEX(Engine_Grid,75+$AB17,$AD17+1)=0),0,INDEX(Engine_Grid,75+$AB17,$AD17)*(1-$AE17)+INDEX(Engine_Grid,75+$AB17,$AD17+1)*$AE17)))*IF(N($D17)<1,1,$D17)) -> 0.3 | AJ17: =IF(N($F17)<=0,0,$F17/100*IF(OR($AB17="",$AC17="",N($AC17)<1,N($AC17)>24),0,IF($AE17=0,INDEX(Engine_Grid,150+$AB17,$AD17),IF(OR($AD17>=24,INDEX(Engine_Grid,150+$AB17,$AD17)=0,INDEX(Engine_Grid,150+$AB17,$AD17+1)=0),0,INDEX(Engine_Grid,150+$AB17,$AD17)*(1-$AE17)+INDEX(Engine_Grid,150+$AB17,$AD17+1)*$AE17)))*IF(N($D17)<1,1,$D17)) -> 0.39 | AK17: =IF(N($F17)<=0,0,$F17/100*IF(OR($AB17="",$AC17="",N($AC17)<1,N($AC17)>24),0,IF($AE17=0,INDEX(Engine_Grid,225+$AB17,$AD17),IF(OR($AD17>=24,INDEX(Engine_Grid,225+$AB17,$AD17)=0,INDEX(Engine_Grid,225+$AB17,$AD17+1)=0),0,INDEX(Engine_Grid,225+$AB17,$AD17)*(1-$AE17)+INDEX(Engine_Grid,225+$AB17,$AD17+1)*$AE17)))*IF(N($D17)<1,1,$D17)) -> 0.3
A18: 9 | B18: Button sew – 4 hole | C18: BS 4 hole | F18: 1 | G18: =IF($AB18="","",IF(INDEX(Lib_Basis,$AB18)="Piece","pcs","cm")) -> pcs | H18: =IF(OR($AB18="",$AC18="",N($AC18)<1,N($AC18)>24),0,IF($AE18=0,INDEX(Engine_Grid,(WeightIdx-1)*75+$AB18,$AD18),IF(OR($AD18>=24,INDEX(Engine_Grid,(WeightIdx-1)*75+$AB18,$AD18)=0,INDEX(Engine_Grid,(WeightIdx-1)*75+$AB18,$AD18+1)=0),0,INDEX(Engine_Grid,(WeightIdx-1)*75+$AB18,$AD18)*(1-$AE18)+INDEX(Engine_Grid,(WeightIdx-1)*75+$AB18,$AD18+1)*$AE18))) -> 14 | I18: =IF(OR($H18=0,N($F18)<=0),0,$F18/100*$H18*IF(N($D18)<1,1,$D18)) -> 0.14 | J18: =IF($AB18="","",INDEX(Lib_Needle,$AB18)) -> 0.7 | K18: =IF($AB18="","",INDEX(Lib_Bobbin,$AB18)) -> 0.3 | L18: =IF($AB18="","",INDEX(Lib_Looper,$AB18)) -> 0 | M18: =IF($AB18="","",INDEX(Lib_Cover,$AB18)) -> 0 | N18: Tex 27 Core Poly – Khaki (bartack / buttonhole) | O18: =IF($I18=0,0,IF($AF18="Y",$I18*$J18/IF(N($D18)<1,1,$D18),$I18*$J18)) -> 0.098 | Q18: =IF(AND($I18>0,$AF18="Y",IF(N($D18)<1,1,$D18)>=2),$I18*$J18/IF(N($D18)<1,1,$D18),0) -> 0 | S18: =IF(AND($I18>0,$AF18="Y",IF(N($D18)<1,1,$D18)>=3),$I18*$J18/IF(N($D18)<1,1,$D18),0) -> 0 | T18: Tex 27 Core Poly – Khaki (bartack / buttonhole) | U18: =IF($I18=0,0,$I18*$K18) -> 0.042 | W18: =IF($I18=0,0,$I18*$L18) -> 0 | Y18: =IF($I18=0,0,$I18*$M18) -> 0 | Z18: =IF($N18="",$O18,0)+IF($P18="",$Q18,0)+IF($R18="",$S18,0)+IF($T18="",$U18,0)+IF($V18="",$W18,0)+IF($X18="",$Y18,0)+IF(AND($AF18="Y",IF(N($D18)<1,1,$D18)>3),$I18*$J18*(IF(N($D18)<1,1,$D18)-3)/IF(N($D18)<1,1,$D18),0) -> 0 | AA18: =IF(AND($C18="",N($F18)=0),"",IF($C18="","⚠ Select a stitch type",IF($AB18="","⚠ Stitch not in library",IF(N($F18)<=0,"⚠ Enter "&IF($G18="pcs","quantity","seam length (cm)"),IF(AND($G18="cm",N($E18)<=0),"⚠ Enter SPI",IF($H18=0,"⚠ No factor at SPI "&$E18&" – valid "&INDEX(Lib_MinSPI,$AB18)&"–"&INDEX(Lib_MaxSPI,$AB18),IF(AND($AF18="Y",IF(N($D18)<1,1,$D18)>3),"⚠ More than 3 rows – thread for extra rows not allocated",IF($Z18>0.00001,"⚠ Assign threads ("&TEXT($Z18,"0.00")&" m unassigned)","✔ OK")))))))) -> ✔ OK | AB18: =IF($C18="","",IFERROR(MATCH($C18,Lib_Names,0),"")) -> 54 | AC18: =IF($AB18="","",IF(INDEX(Lib_Basis,$AB18)="Piece",1,N($E18))) -> 1 | AD18: =IF($AC18="","",INT($AC18)) -> 1 | AE18: =IF($AC18="","",$AC18-$AD18) -> 0 | AF18: =IF($AB18="","",INDEX(Lib_Multi,$AB18)) -> N | AG18: =IF($AB18="","",INDEX(Lib_Cat,$AB18)) -> Button sew | AH18: =IF(N($F18)<=0,0,$F18/100*IF(OR($AB18="",$AC18="",N($AC18)<1,N($AC18)>24),0,IF($AE18=0,INDEX(Engine_Grid,0+$AB18,$AD18),IF(OR($AD18>=24,INDEX(Engine_Grid,0+$AB18,$AD18)=0,INDEX(Engine_Grid,0+$AB18,$AD18+1)=0),0,INDEX(Engine_Grid,0+$AB18,$AD18)*(1-$AE18)+INDEX(Engine_Grid,0+$AB18,$AD18+1)*$AE18)))*IF(N($D18)<1,1,$D18)) -> 0.08 | AI18: =IF(N($F18)<=0,0,$F18/100*IF(OR($AB18="",$AC18="",N($AC18)<1,N($AC18)>24),0,IF($AE18=0,INDEX(Engine_Grid,75+$AB18,$AD18),IF(OR($AD18>=24,INDEX(Engine_Grid,75+$AB18,$AD18)=0,INDEX(Engine_Grid,75+$AB18,$AD18+1)=0),0,INDEX(Engine_Grid,75+$AB18,$AD18)*(1-$AE18)+INDEX(Engine_Grid,75+$AB18,$AD18+1)*$AE18)))*IF(N($D18)<1,1,$D18)) -> 0.14 | AJ18: =IF(N($F18)<=0,0,$F18/100*IF(OR($AB18="",$AC18="",N($AC18)<1,N($AC18)>24),0,IF($AE18=0,INDEX(Engine_Grid,150+$AB18,$AD18),IF(OR($AD18>=24,INDEX(Engine_Grid,150+$AB18,$AD18)=0,INDEX(Engine_Grid,150+$AB18,$AD18+1)=0),0,INDEX(Engine_Grid,150+$AB18,$AD18)*(1-$AE18)+INDEX(Engine_Grid,150+$AB18,$AD18+1)*$AE18)))*IF(N($D18)<1,1,$D18)) -> 0.18 | AK18: =IF(N($F18)<=0,0,$F18/100*IF(OR($AB18="",$AC18="",N($AC18)<1,N($AC18)>24),0,IF($AE18=0,INDEX(Engine_Grid,225+$AB18,$AD18),IF(OR($AD18>=24,INDEX(Engine_Grid,225+$AB18,$AD18)=0,INDEX(Engine_Grid,225+$AB18,$AD18+1)=0),0,INDEX(Engine_Grid,225+$AB18,$AD18)*(1-$AE18)+INDEX(Engine_Grid,225+$AB18,$AD18+1)*$AE18)))*IF(N($D18)<1,1,$D18)) -> 0.14
A19: 10 | G19: =IF($AB19="","",IF(INDEX(Lib_Basis,$AB19)="Piece","pcs","cm")) | H19: =IF(OR($AB19="",$AC19="",N($AC19)<1,N($AC19)>24),0,IF($AE19=0,INDEX(Engine_Grid,(WeightIdx-1)*75+$AB19,$AD19),IF(OR($AD19>=24,INDEX(Engine_Grid,(WeightIdx-1)*75+$AB19,$AD19)=0,INDEX(Engine_Grid,(WeightIdx-1)*75+$AB19,$AD19+1)=0),0,INDEX(Engine_Grid,(WeightIdx-1)*75+$AB19,$AD19)*(1-$AE19)+INDEX(Engine_Grid,(WeightIdx-1)*75+$AB19,$AD19+1)*$AE19))) -> 0 | I19: =IF(OR($H19=0,N($F19)<=0),0,$F19/100*$H19*IF(N($D19)<1,1,$D19)) -> 0 | J19: =IF($AB19="","",INDEX(Lib_Needle,$AB19)) | K19: =IF($AB19="","",INDEX(Lib_Bobbin,$AB19)) | L19: =IF($AB19="","",INDEX(Lib_Looper,$AB19)) | M19: =IF($AB19="","",INDEX(Lib_Cover,$AB19)) | O19: =IF($I19=0,0,IF($AF19="Y",$I19*$J19/IF(N($D19)<1,1,$D19),$I19*$J19)) -> 0 | Q19: =IF(AND($I19>0,$AF19="Y",IF(N($D19)<1,1,$D19)>=2),$I19*$J19/IF(N($D19)<1,1,$D19),0) -> 0 | S19: =IF(AND($I19>0,$AF19="Y",IF(N($D19)<1,1,$D19)>=3),$I19*$J19/IF(N($D19)<1,1,$D19),0) -> 0 | U19: =IF($I19=0,0,$I19*$K19) -> 0 | W19: =IF($I19=0,0,$I19*$L19) -> 0 | Y19: =IF($I19=0,0,$I19*$M19) -> 0 | Z19: =IF($N19="",$O19,0)+IF($P19="",$Q19,0)+IF($R19="",$S19,0)+IF($T19="",$U19,0)+IF($V19="",$W19,0)+IF($X19="",$Y19,0)+IF(AND($AF19="Y",IF(N($D19)<1,1,$D19)>3),$I19*$J19*(IF(N($D19)<1,1,$D19)-3)/IF(N($D19)<1,1,$D19),0) -> 0 | AA19: =IF(AND($C19="",N($F19)=0),"",IF($C19="","⚠ Select a stitch type",IF($AB19="","⚠ Stitch not in library",IF(N($F19)<=0,"⚠ Enter "&IF($G19="pcs","quantity","seam length (cm)"),IF(AND($G19="cm",N($E19)<=0),"⚠ Enter SPI",IF($H19=0,"⚠ No factor at SPI "&$E19&" – valid "&INDEX(Lib_MinSPI,$AB19)&"–"&INDEX(Lib_MaxSPI,$AB19),IF(AND($AF19="Y",IF(N($D19)<1,1,$D19)>3),"⚠ More than 3 rows – thread for extra rows not allocated",IF($Z19>0.00001,"⚠ Assign threads ("&TEXT($Z19,"0.00")&" m unassigned)","✔ OK")))))))) | AB19: =IF($C19="","",IFERROR(MATCH($C19,Lib_Names,0),"")) | AC19: =IF($AB19="","",IF(INDEX(Lib_Basis,$AB19)="Piece",1,N($E19))) | AD19: =IF($AC19="","",INT($AC19)) | AE19: =IF($AC19="","",$AC19-$AD19) | AF19: =IF($AB19="","",INDEX(Lib_Multi,$AB19)) | AG19: =IF($AB19="","",INDEX(Lib_Cat,$AB19)) | AH19: =IF(N($F19)<=0,0,$F19/100*IF(OR($AB19="",$AC19="",N($AC19)<1,N($AC19)>24),0,IF($AE19=0,INDEX(Engine_Grid,0+$AB19,$AD19),IF(OR($AD19>=24,INDEX(Engine_Grid,0+$AB19,$AD19)=0,INDEX(Engine_Grid,0+$AB19,$AD19+1)=0),0,INDEX(Engine_Grid,0+$AB19,$AD19)*(1-$AE19)+INDEX(Engine_Grid,0+$AB19,$AD19+1)*$AE19)))*IF(N($D19)<1,1,$D19)) -> 0 | AI19: =IF(N($F19)<=0,0,$F19/100*IF(OR($AB19="",$AC19="",N($AC19)<1,N($AC19)>24),0,IF($AE19=0,INDEX(Engine_Grid,75+$AB19,$AD19),IF(OR($AD19>=24,INDEX(Engine_Grid,75+$AB19,$AD19)=0,INDEX(Engine_Grid,75+$AB19,$AD19+1)=0),0,INDEX(Engine_Grid,75+$AB19,$AD19)*(1-$AE19)+INDEX(Engine_Grid,75+$AB19,$AD19+1)*$AE19)))*IF(N($D19)<1,1,$D19)) -> 0 | AJ19: =IF(N($F19)<=0,0,$F19/100*IF(OR($AB19="",$AC19="",N($AC19)<1,N($AC19)>24),0,IF($AE19=0,INDEX(Engine_Grid,150+$AB19,$AD19),IF(OR($AD19>=24,INDEX(Engine_Grid,150+$AB19,$AD19)=0,INDEX(Engine_Grid,150+$AB19,$AD19+1)=0),0,INDEX(Engine_Grid,150+$AB19,$AD19)*(1-$AE19)+INDEX(Engine_Grid,150+$AB19,$AD19+1)*$AE19)))*IF(N($D19)<1,1,$D19)) -> 0 | AK19: =IF(N($F19)<=0,0,$F19/100*IF(OR($AB19="",$AC19="",N($AC19)<1,N($AC19)>24),0,IF($AE19=0,INDEX(Engine_Grid,225+$AB19,$AD19),IF(OR($AD19>=24,INDEX(Engine_Grid,225+$AB19,$AD19)=0,INDEX(Engine_Grid,225+$AB19,$AD19+1)=0),0,INDEX(Engine_Grid,225+$AB19,$AD19)*(1-$AE19)+INDEX(Engine_Grid,225+$AB19,$AD19+1)*$AE19)))*IF(N($D19)<1,1,$D19)) -> 0
A20: 11 | G20: =IF($AB20="","",IF(INDEX(Lib_Basis,$AB20)="Piece","pcs","cm")) | H20: =IF(OR($AB20="",$AC20="",N($AC20)<1,N($AC20)>24),0,IF($AE20=0,INDEX(Engine_Grid,(WeightIdx-1)*75+$AB20,$AD20),IF(OR($AD20>=24,INDEX(Engine_Grid,(WeightIdx-1)*75+$AB20,$AD20)=0,INDEX(Engine_Grid,(WeightIdx-1)*75+$AB20,$AD20+1)=0),0,INDEX(Engine_Grid,(WeightIdx-1)*75+$AB20,$AD20)*(1-$AE20)+INDEX(Engine_Grid,(WeightIdx-1)*75+$AB20,$AD20+1)*$AE20))) -> 0 | I20: =IF(OR($H20=0,N($F20)<=0),0,$F20/100*$H20*IF(N($D20)<1,1,$D20)) -> 0 | J20: =IF($AB20="","",INDEX(Lib_Needle,$AB20)) | K20: =IF($AB20="","",INDEX(Lib_Bobbin,$AB20)) | L20: =IF($AB20="","",INDEX(Lib_Looper,$AB20)) | M20: =IF($AB20="","",INDEX(Lib_Cover,$AB20)) | O20: =IF($I20=0,0,IF($AF20="Y",$I20*$J20/IF(N($D20)<1,1,$D20),$I20*$J20)) -> 0 | Q20: =IF(AND($I20>0,$AF20="Y",IF(N($D20)<1,1,$D20)>=2),$I20*$J20/IF(N($D20)<1,1,$D20),0) -> 0 | S20: =IF(AND($I20>0,$AF20="Y",IF(N($D20)<1,1,$D20)>=3),$I20*$J20/IF(N($D20)<1,1,$D20),0) -> 0 | U20: =IF($I20=0,0,$I20*$K20) -> 0 | W20: =IF($I20=0,0,$I20*$L20) -> 0 | Y20: =IF($I20=0,0,$I20*$M20) -> 0 | Z20: =IF($N20="",$O20,0)+IF($P20="",$Q20,0)+IF($R20="",$S20,0)+IF($T20="",$U20,0)+IF($V20="",$W20,0)+IF($X20="",$Y20,0)+IF(AND($AF20="Y",IF(N($D20)<1,1,$D20)>3),$I20*$J20*(IF(N($D20)<1,1,$D20)-3)/IF(N($D20)<1,1,$D20),0) -> 0 | AA20: =IF(AND($C20="",N($F20)=0),"",IF($C20="","⚠ Select a stitch type",IF($AB20="","⚠ Stitch not in library",IF(N($F20)<=0,"⚠ Enter "&IF($G20="pcs","quantity","seam length (cm)"),IF(AND($G20="cm",N($E20)<=0),"⚠ Enter SPI",IF($H20=0,"⚠ No factor at SPI "&$E20&" – valid "&INDEX(Lib_MinSPI,$AB20)&"–"&INDEX(Lib_MaxSPI,$AB20),IF(AND($AF20="Y",IF(N($D20)<1,1,$D20)>3),"⚠ More than 3 rows – thread for extra rows not allocated",IF($Z20>0.00001,"⚠ Assign threads ("&TEXT($Z20,"0.00")&" m unassigned)","✔ OK")))))))) | AB20: =IF($C20="","",IFERROR(MATCH($C20,Lib_Names,0),"")) | AC20: =IF($AB20="","",IF(INDEX(Lib_Basis,$AB20)="Piece",1,N($E20))) | AD20: =IF($AC20="","",INT($AC20)) | AE20: =IF($AC20="","",$AC20-$AD20) | AF20: =IF($AB20="","",INDEX(Lib_Multi,$AB20)) | AG20: =IF($AB20="","",INDEX(Lib_Cat,$AB20)) | AH20: =IF(N($F20)<=0,0,$F20/100*IF(OR($AB20="",$AC20="",N($AC20)<1,N($AC20)>24),0,IF($AE20=0,INDEX(Engine_Grid,0+$AB20,$AD20),IF(OR($AD20>=24,INDEX(Engine_Grid,0+$AB20,$AD20)=0,INDEX(Engine_Grid,0+$AB20,$AD20+1)=0),0,INDEX(Engine_Grid,0+$AB20,$AD20)*(1-$AE20)+INDEX(Engine_Grid,0+$AB20,$AD20+1)*$AE20)))*IF(N($D20)<1,1,$D20)) -> 0 | AI20: =IF(N($F20)<=0,0,$F20/100*IF(OR($AB20="",$AC20="",N($AC20)<1,N($AC20)>24),0,IF($AE20=0,INDEX(Engine_Grid,75+$AB20,$AD20),IF(OR($AD20>=24,INDEX(Engine_Grid,75+$AB20,$AD20)=0,INDEX(Engine_Grid,75+$AB20,$AD20+1)=0),0,INDEX(Engine_Grid,75+$AB20,$AD20)*(1-$AE20)+INDEX(Engine_Grid,75+$AB20,$AD20+1)*$AE20)))*IF(N($D20)<1,1,$D20)) -> 0 | AJ20: =IF(N($F20)<=0,0,$F20/100*IF(OR($AB20="",$AC20="",N($AC20)<1,N($AC20)>24),0,IF($AE20=0,INDEX(Engine_Grid,150+$AB20,$AD20),IF(OR($AD20>=24,INDEX(Engine_Grid,150+$AB20,$AD20)=0,INDEX(Engine_Grid,150+$AB20,$AD20+1)=0),0,INDEX(Engine_Grid,150+$AB20,$AD20)*(1-$AE20)+INDEX(Engine_Grid,150+$AB20,$AD20+1)*$AE20)))*IF(N($D20)<1,1,$D20)) -> 0 | AK20: =IF(N($F20)<=0,0,$F20/100*IF(OR($AB20="",$AC20="",N($AC20)<1,N($AC20)>24),0,IF($AE20=0,INDEX(Engine_Grid,225+$AB20,$AD20),IF(OR($AD20>=24,INDEX(Engine_Grid,225+$AB20,$AD20)=0,INDEX(Engine_Grid,225+$AB20,$AD20+1)=0),0,INDEX(Engine_Grid,225+$AB20,$AD20)*(1-$AE20)+INDEX(Engine_Grid,225+$AB20,$AD20+1)*$AE20)))*IF(N($D20)<1,1,$D20)) -> 0
A21: 12 | G21: =IF($AB21="","",IF(INDEX(Lib_Basis,$AB21)="Piece","pcs","cm")) | H21: =IF(OR($AB21="",$AC21="",N($AC21)<1,N($AC21)>24),0,IF($AE21=0,INDEX(Engine_Grid,(WeightIdx-1)*75+$AB21,$AD21),IF(OR($AD21>=24,INDEX(Engine_Grid,(WeightIdx-1)*75+$AB21,$AD21)=0,INDEX(Engine_Grid,(WeightIdx-1)*75+$AB21,$AD21+1)=0),0,INDEX(Engine_Grid,(WeightIdx-1)*75+$AB21,$AD21)*(1-$AE21)+INDEX(Engine_Grid,(WeightIdx-1)*75+$AB21,$AD21+1)*$AE21))) -> 0 | I21: =IF(OR($H21=0,N($F21)<=0),0,$F21/100*$H21*IF(N($D21)<1,1,$D21)) -> 0 | J21: =IF($AB21="","",INDEX(Lib_Needle,$AB21)) | K21: =IF($AB21="","",INDEX(Lib_Bobbin,$AB21)) | L21: =IF($AB21="","",INDEX(Lib_Looper,$AB21)) | M21: =IF($AB21="","",INDEX(Lib_Cover,$AB21)) | O21: =IF($I21=0,0,IF($AF21="Y",$I21*$J21/IF(N($D21)<1,1,$D21),$I21*$J21)) -> 0 | Q21: =IF(AND($I21>0,$AF21="Y",IF(N($D21)<1,1,$D21)>=2),$I21*$J21/IF(N($D21)<1,1,$D21),0) -> 0 | S21: =IF(AND($I21>0,$AF21="Y",IF(N($D21)<1,1,$D21)>=3),$I21*$J21/IF(N($D21)<1,1,$D21),0) -> 0 | U21: =IF($I21=0,0,$I21*$K21) -> 0 | W21: =IF($I21=0,0,$I21*$L21) -> 0 | Y21: =IF($I21=0,0,$I21*$M21) -> 0 | Z21: =IF($N21="",$O21,0)+IF($P21="",$Q21,0)+IF($R21="",$S21,0)+IF($T21="",$U21,0)+IF($V21="",$W21,0)+IF($X21="",$Y21,0)+IF(AND($AF21="Y",IF(N($D21)<1,1,$D21)>3),$I21*$J21*(IF(N($D21)<1,1,$D21)-3)/IF(N($D21)<1,1,$D21),0) -> 0 | AA21: =IF(AND($C21="",N($F21)=0),"",IF($C21="","⚠ Select a stitch type",IF($AB21="","⚠ Stitch not in library",IF(N($F21)<=0,"⚠ Enter "&IF($G21="pcs","quantity","seam length (cm)"),IF(AND($G21="cm",N($E21)<=0),"⚠ Enter SPI",IF($H21=0,"⚠ No factor at SPI "&$E21&" – valid "&INDEX(Lib_MinSPI,$AB21)&"–"&INDEX(Lib_MaxSPI,$AB21),IF(AND($AF21="Y",IF(N($D21)<1,1,$D21)>3),"⚠ More than 3 rows – thread for extra rows not allocated",IF($Z21>0.00001,"⚠ Assign threads ("&TEXT($Z21,"0.00")&" m unassigned)","✔ OK")))))))) | AB21: =IF($C21="","",IFERROR(MATCH($C21,Lib_Names,0),"")) | AC21: =IF($AB21="","",IF(INDEX(Lib_Basis,$AB21)="Piece",1,N($E21))) | AD21: =IF($AC21="","",INT($AC21)) | AE21: =IF($AC21="","",$AC21-$AD21) | AF21: =IF($AB21="","",INDEX(Lib_Multi,$AB21)) | AG21: =IF($AB21="","",INDEX(Lib_Cat,$AB21)) | AH21: =IF(N($F21)<=0,0,$F21/100*IF(OR($AB21="",$AC21="",N($AC21)<1,N($AC21)>24),0,IF($AE21=0,INDEX(Engine_Grid,0+$AB21,$AD21),IF(OR($AD21>=24,INDEX(Engine_Grid,0+$AB21,$AD21)=0,INDEX(Engine_Grid,0+$AB21,$AD21+1)=0),0,INDEX(Engine_Grid,0+$AB21,$AD21)*(1-$AE21)+INDEX(Engine_Grid,0+$AB21,$AD21+1)*$AE21)))*IF(N($D21)<1,1,$D21)) -> 0 | AI21: =IF(N($F21)<=0,0,$F21/100*IF(OR($AB21="",$AC21="",N($AC21)<1,N($AC21)>24),0,IF($AE21=0,INDEX(Engine_Grid,75+$AB21,$AD21),IF(OR($AD21>=24,INDEX(Engine_Grid,75+$AB21,$AD21)=0,INDEX(Engine_Grid,75+$AB21,$AD21+1)=0),0,INDEX(Engine_Grid,75+$AB21,$AD21)*(1-$AE21)+INDEX(Engine_Grid,75+$AB21,$AD21+1)*$AE21)))*IF(N($D21)<1,1,$D21)) -> 0 | AJ21: =IF(N($F21)<=0,0,$F21/100*IF(OR($AB21="",$AC21="",N($AC21)<1,N($AC21)>24),0,IF($AE21=0,INDEX(Engine_Grid,150+$AB21,$AD21),IF(OR($AD21>=24,INDEX(Engine_Grid,150+$AB21,$AD21)=0,INDEX(Engine_Grid,150+$AB21,$AD21+1)=0),0,INDEX(Engine_Grid,150+$AB21,$AD21)*(1-$AE21)+INDEX(Engine_Grid,150+$AB21,$AD21+1)*$AE21)))*IF(N($D21)<1,1,$D21)) -> 0 | AK21: =IF(N($F21)<=0,0,$F21/100*IF(OR($AB21="",$AC21="",N($AC21)<1,N($AC21)>24),0,IF($AE21=0,INDEX(Engine_Grid,225+$AB21,$AD21),IF(OR($AD21>=24,INDEX(Engine_Grid,225+$AB21,$AD21)=0,INDEX(Engine_Grid,225+$AB21,$AD21+1)=0),0,INDEX(Engine_Grid,225+$AB21,$AD21)*(1-$AE21)+INDEX(Engine_Grid,225+$AB21,$AD21+1)*$AE21)))*IF(N($D21)<1,1,$D21)) -> 0
A22: 13 | G22: =IF($AB22="","",IF(INDEX(Lib_Basis,$AB22)="Piece","pcs","cm")) | H22: =IF(OR($AB22="",$AC22="",N($AC22)<1,N($AC22)>24),0,IF($AE22=0,INDEX(Engine_Grid,(WeightIdx-1)*75+$AB22,$AD22),IF(OR($AD22>=24,INDEX(Engine_Grid,(WeightIdx-1)*75+$AB22,$AD22)=0,INDEX(Engine_Grid,(WeightIdx-1)*75+$AB22,$AD22+1)=0),0,INDEX(Engine_Grid,(WeightIdx-1)*75+$AB22,$AD22)*(1-$AE22)+INDEX(Engine_Grid,(WeightIdx-1)*75+$AB22,$AD22+1)*$AE22))) -> 0 | I22: =IF(OR($H22=0,N($F22)<=0),0,$F22/100*$H22*IF(N($D22)<1,1,$D22)) -> 0 | J22: =IF($AB22="","",INDEX(Lib_Needle,$AB22)) | K22: =IF($AB22="","",INDEX(Lib_Bobbin,$AB22)) | L22: =IF($AB22="","",INDEX(Lib_Looper,$AB22)) | M22: =IF($AB22="","",INDEX(Lib_Cover,$AB22)) | O22: =IF($I22=0,0,IF($AF22="Y",$I22*$J22/IF(N($D22)<1,1,$D22),$I22*$J22)) -> 0 | Q22: =IF(AND($I22>0,$AF22="Y",IF(N($D22)<1,1,$D22)>=2),$I22*$J22/IF(N($D22)<1,1,$D22),0) -> 0 | S22: =IF(AND($I22>0,$AF22="Y",IF(N($D22)<1,1,$D22)>=3),$I22*$J22/IF(N($D22)<1,1,$D22),0) -> 0 | U22: =IF($I22=0,0,$I22*$K22) -> 0 | W22: =IF($I22=0,0,$I22*$L22) -> 0 | Y22: =IF($I22=0,0,$I22*$M22) -> 0 | Z22: =IF($N22="",$O22,0)+IF($P22="",$Q22,0)+IF($R22="",$S22,0)+IF($T22="",$U22,0)+IF($V22="",$W22,0)+IF($X22="",$Y22,0)+IF(AND($AF22="Y",IF(N($D22)<1,1,$D22)>3),$I22*$J22*(IF(N($D22)<1,1,$D22)-3)/IF(N($D22)<1,1,$D22),0) -> 0 | AA22: =IF(AND($C22="",N($F22)=0),"",IF($C22="","⚠ Select a stitch type",IF($AB22="","⚠ Stitch not in library",IF(N($F22)<=0,"⚠ Enter "&IF($G22="pcs","quantity","seam length (cm)"),IF(AND($G22="cm",N($E22)<=0),"⚠ Enter SPI",IF($H22=0,"⚠ No factor at SPI "&$E22&" – valid "&INDEX(Lib_MinSPI,$AB22)&"–"&INDEX(Lib_MaxSPI,$AB22),IF(AND($AF22="Y",IF(N($D22)<1,1,$D22)>3),"⚠ More than 3 rows – thread for extra rows not allocated",IF($Z22>0.00001,"⚠ Assign threads ("&TEXT($Z22,"0.00")&" m unassigned)","✔ OK")))))))) | AB22: =IF($C22="","",IFERROR(MATCH($C22,Lib_Names,0),"")) | AC22: =IF($AB22="","",IF(INDEX(Lib_Basis,$AB22)="Piece",1,N($E22))) | AD22: =IF($AC22="","",INT($AC22)) | AE22: =IF($AC22="","",$AC22-$AD22) | AF22: =IF($AB22="","",INDEX(Lib_Multi,$AB22)) | AG22: =IF($AB22="","",INDEX(Lib_Cat,$AB22)) | AH22: =IF(N($F22)<=0,0,$F22/100*IF(OR($AB22="",$AC22="",N($AC22)<1,N($AC22)>24),0,IF($AE22=0,INDEX(Engine_Grid,0+$AB22,$AD22),IF(OR($AD22>=24,INDEX(Engine_Grid,0+$AB22,$AD22)=0,INDEX(Engine_Grid,0+$AB22,$AD22+1)=0),0,INDEX(Engine_Grid,0+$AB22,$AD22)*(1-$AE22)+INDEX(Engine_Grid,0+$AB22,$AD22+1)*$AE22)))*IF(N($D22)<1,1,$D22)) -> 0 | AI22: =IF(N($F22)<=0,0,$F22/100*IF(OR($AB22="",$AC22="",N($AC22)<1,N($AC22)>24),0,IF($AE22=0,INDEX(Engine_Grid,75+$AB22,$AD22),IF(OR($AD22>=24,INDEX(Engine_Grid,75+$AB22,$AD22)=0,INDEX(Engine_Grid,75+$AB22,$AD22+1)=0),0,INDEX(Engine_Grid,75+$AB22,$AD22)*(1-$AE22)+INDEX(Engine_Grid,75+$AB22,$AD22+1)*$AE22)))*IF(N($D22)<1,1,$D22)) -> 0 | AJ22: =IF(N($F22)<=0,0,$F22/100*IF(OR($AB22="",$AC22="",N($AC22)<1,N($AC22)>24),0,IF($AE22=0,INDEX(Engine_Grid,150+$AB22,$AD22),IF(OR($AD22>=24,INDEX(Engine_Grid,150+$AB22,$AD22)=0,INDEX(Engine_Grid,150+$AB22,$AD22+1)=0),0,INDEX(Engine_Grid,150+$AB22,$AD22)*(1-$AE22)+INDEX(Engine_Grid,150+$AB22,$AD22+1)*$AE22)))*IF(N($D22)<1,1,$D22)) -> 0 | AK22: =IF(N($F22)<=0,0,$F22/100*IF(OR($AB22="",$AC22="",N($AC22)<1,N($AC22)>24),0,IF($AE22=0,INDEX(Engine_Grid,225+$AB22,$AD22),IF(OR($AD22>=24,INDEX(Engine_Grid,225+$AB22,$AD22)=0,INDEX(Engine_Grid,225+$AB22,$AD22+1)=0),0,INDEX(Engine_Grid,225+$AB22,$AD22)*(1-$AE22)+INDEX(Engine_Grid,225+$AB22,$AD22+1)*$AE22)))*IF(N($D22)<1,1,$D22)) -> 0
